[0m18:08:06.482768 [debug] [MainThread]: Sending event: {'category': 'dbt', 'action': 'invocation', 'label': 'start', 'context': [<snowplow_tracker.self_describing_json.SelfDescribingJson object at 0x00000232A83D9160>, <snowplow_tracker.self_describing_json.SelfDescribingJson object at 0x00000232A6528E10>, <snowplow_tracker.self_describing_json.SelfDescribingJson object at 0x00000232A902E490>]}


============================== 18:08:06.486429 | d6f8512d-436f-489b-a7d6-f4e247935940 ==============================
[0m18:08:06.486429 [info ] [MainThread]: Running with dbt=1.9.1
[0m18:08:06.487119 [debug] [MainThread]: running dbt with arguments {'printer_width': '80', 'indirect_selection': 'eager', 'log_cache_events': 'False', 'write_json': 'True', 'partial_parse': 'True', 'cache_selected_only': 'False', 'warn_error': 'None', 'version_check': 'True', 'profiles_dir': 'C:\\Users\\geron\\.dbt', 'log_path': 'logs', 'fail_fast': 'False', 'debug': 'False', 'use_colors': 'True', 'use_experimental_parser': 'False', 'empty': 'None', 'quiet': 'False', 'no_print': 'None', 'warn_error_options': 'WarnErrorOptions(include=[], exclude=[])', 'introspect': 'True', 'log_format': 'default', 'static_parser': 'True', 'target_path': 'None', 'invocation_command': 'dbt init', 'send_anonymous_usage_stats': 'True'}
[0m18:08:06.501595 [warn ] [MainThread]: [ConfigFolderDirectory]: Unable to parse logging event dictionary. Failed to parse dir field: expected string or bytes-like object, got 'WindowsPath'.. Dictionary: {'dir': WindowsPath('C:/Users/geron/.dbt')}
[0m18:08:06.502129 [info ] [MainThread]: Creating dbt configuration folder at 
[0m18:08:10.661905 [debug] [MainThread]: Starter project path: C:\Users\geron\Desktop\Projetos-Pessoais\magazord-etl\.venv\Lib\site-packages\dbt\include\starter_project
[0m18:08:10.673633 [info ] [MainThread]: 
Your new dbt project "magazorddw" was created!

For more information on how to configure the profiles.yml file,
please consult the dbt documentation here:

  https://docs.getdbt.com/docs/configure-your-profile

One more thing:

Need help? Don't hesitate to reach out to us via GitHub issues or on Slack:

  https://community.getdbt.com/

Happy modeling!

[0m18:08:10.674295 [info ] [MainThread]: Setting up your profile.
[0m18:08:36.408596 [info ] [MainThread]: Profile magazorddw written to C:\Users\geron\.dbt\profiles.yml using target's profile_template.yml and your supplied values. Run 'dbt debug' to validate the connection.
[0m18:08:36.409570 [debug] [MainThread]: Command `dbt init` succeeded at 18:08:36.409459 after 30.07 seconds
[0m18:08:36.409875 [debug] [MainThread]: Sending event: {'category': 'dbt', 'action': 'invocation', 'label': 'end', 'context': [<snowplow_tracker.self_describing_json.SelfDescribingJson object at 0x00000232A96C4B00>, <snowplow_tracker.self_describing_json.SelfDescribingJson object at 0x00000232A9592210>, <snowplow_tracker.self_describing_json.SelfDescribingJson object at 0x00000232A93A6AD0>]}
[0m18:08:36.410214 [debug] [MainThread]: Flushing usage events
[0m18:08:37.124553 [debug] [MainThread]: An error was encountered while trying to flush usage events
[0m20:18:51.356598 [debug] [MainThread]: Sending event: {'category': 'dbt', 'action': 'invocation', 'label': 'start', 'context': [<snowplow_tracker.self_describing_json.SelfDescribingJson object at 0x000001DB527DCEC0>, <snowplow_tracker.self_describing_json.SelfDescribingJson object at 0x000001DB509C8A50>, <snowplow_tracker.self_describing_json.SelfDescribingJson object at 0x000001DB5340E350>]}


============================== 20:18:51.362450 | 4992916a-8dc2-4623-8850-b4952fc04718 ==============================
[0m20:18:51.362450 [info ] [MainThread]: Running with dbt=1.9.1
[0m20:18:51.363168 [debug] [MainThread]: running dbt with arguments {'printer_width': '80', 'indirect_selection': 'eager', 'log_cache_events': 'False', 'write_json': 'True', 'partial_parse': 'True', 'cache_selected_only': 'False', 'profiles_dir': 'C:\\Users\\geron\\Desktop\\Projetos-Pessoais\\magazord-etl', 'version_check': 'True', 'fail_fast': 'False', 'log_path': 'logs', 'warn_error': 'None', 'debug': 'False', 'use_colors': 'True', 'use_experimental_parser': 'False', 'no_print': 'None', 'quiet': 'False', 'empty': 'False', 'log_format': 'default', 'static_parser': 'True', 'warn_error_options': 'WarnErrorOptions(include=[], exclude=[])', 'introspect': 'True', 'target_path': 'None', 'invocation_command': 'dbt run', 'send_anonymous_usage_stats': 'True'}
[0m20:18:51.363610 [error] [MainThread]: Encountered an error:
Runtime Error
  No dbt_project.yml found at expected path C:\Users\geron\Desktop\Projetos-Pessoais\magazord-etl\dbt_project.yml
  Verify that each entry within packages.yml (and their transitive dependencies) contains a file named dbt_project.yml
  
[0m20:18:51.364316 [debug] [MainThread]: Command `dbt run` failed at 20:18:51.364209 after 0.21 seconds
[0m20:18:51.364610 [debug] [MainThread]: Sending event: {'category': 'dbt', 'action': 'invocation', 'label': 'end', 'context': [<snowplow_tracker.self_describing_json.SelfDescribingJson object at 0x000001DB5390C770>, <snowplow_tracker.self_describing_json.SelfDescribingJson object at 0x000001DB53904EF0>, <snowplow_tracker.self_describing_json.SelfDescribingJson object at 0x000001DB53789F20>]}
[0m20:18:51.364922 [debug] [MainThread]: Flushing usage events
[0m20:18:52.266950 [debug] [MainThread]: An error was encountered while trying to flush usage events
[0m20:19:09.876923 [debug] [MainThread]: Sending event: {'category': 'dbt', 'action': 'invocation', 'label': 'start', 'context': [<snowplow_tracker.self_describing_json.SelfDescribingJson object at 0x000002177876CEC0>, <snowplow_tracker.self_describing_json.SelfDescribingJson object at 0x00000217768F8A50>, <snowplow_tracker.self_describing_json.SelfDescribingJson object at 0x00000217793AE350>]}


============================== 20:19:09.881635 | f49996af-4546-47b1-aac4-2e98f05c4882 ==============================
[0m20:19:09.881635 [info ] [MainThread]: Running with dbt=1.9.1
[0m20:19:09.882354 [debug] [MainThread]: running dbt with arguments {'printer_width': '80', 'indirect_selection': 'eager', 'write_json': 'True', 'log_cache_events': 'False', 'partial_parse': 'True', 'cache_selected_only': 'False', 'warn_error': 'None', 'debug': 'False', 'version_check': 'True', 'log_path': 'logs', 'fail_fast': 'False', 'profiles_dir': 'C:\\Users\\geron\\Desktop\\Projetos-Pessoais\\magazord-etl', 'use_colors': 'True', 'use_experimental_parser': 'False', 'empty': 'None', 'quiet': 'False', 'no_print': 'None', 'log_format': 'default', 'introspect': 'True', 'static_parser': 'True', 'warn_error_options': 'WarnErrorOptions(include=[], exclude=[])', 'target_path': 'None', 'invocation_command': 'dbt init', 'send_anonymous_usage_stats': 'True'}
[0m20:19:23.577262 [error] [MainThread]: Encountered an error:

[0m20:19:23.580739 [error] [MainThread]: Traceback (most recent call last):
  File "C:\Users\geron\Desktop\Projetos-Pessoais\magazord-etl\.venv\Lib\site-packages\dbt\cli\requires.py", line 153, in wrapper
    result, success = func(*args, **kwargs)
                      ~~~~^^^^^^^^^^^^^^^^^
  File "C:\Users\geron\Desktop\Projetos-Pessoais\magazord-etl\.venv\Lib\site-packages\dbt\cli\requires.py", line 103, in wrapper
    return func(*args, **kwargs)
  File "C:\Users\geron\Desktop\Projetos-Pessoais\magazord-etl\.venv\Lib\site-packages\dbt\cli\main.py", line 477, in init
    results = task.run()
  File "C:\Users\geron\Desktop\Projetos-Pessoais\magazord-etl\.venv\Lib\site-packages\dbt\task\init.py", line 324, in run
    project_name = self.get_valid_project_name()
  File "C:\Users\geron\Desktop\Projetos-Pessoais\magazord-etl\.venv\Lib\site-packages\dbt\task\init.py", line 278, in get_valid_project_name
    name = click.prompt("Enter a name for your project (letters, digits, underscore)")
  File "C:\Users\geron\Desktop\Projetos-Pessoais\magazord-etl\.venv\Lib\site-packages\click\termui.py", line 164, in prompt
    value = prompt_func(prompt)
  File "C:\Users\geron\Desktop\Projetos-Pessoais\magazord-etl\.venv\Lib\site-packages\click\termui.py", line 147, in prompt_func
    raise Abort() from None
click.exceptions.Abort

[0m20:19:23.581875 [debug] [MainThread]: Command `dbt init` failed at 20:19:23.581749 after 13.84 seconds
[0m20:19:23.582206 [debug] [MainThread]: Sending event: {'category': 'dbt', 'action': 'invocation', 'label': 'end', 'context': [<snowplow_tracker.self_describing_json.SelfDescribingJson object at 0x00000217798A9E00>, <snowplow_tracker.self_describing_json.SelfDescribingJson object at 0x0000021779921010>, <snowplow_tracker.self_describing_json.SelfDescribingJson object at 0x000002177972A9C0>]}
[0m20:19:23.582547 [debug] [MainThread]: Flushing usage events
[0m20:19:24.357289 [debug] [MainThread]: An error was encountered while trying to flush usage events
[0m17:32:55.768587 [debug] [MainThread]: Sending event: {'category': 'dbt', 'action': 'invocation', 'label': 'start', 'context': [<snowplow_tracker.self_describing_json.SelfDescribingJson object at 0x7f5891cc9160>, <snowplow_tracker.self_describing_json.SelfDescribingJson object at 0x7f58930dce10>, <snowplow_tracker.self_describing_json.SelfDescribingJson object at 0x7f5891027ed0>]}


============================== 17:32:55.777842 | abe174d8-87ce-4fdc-8a7d-9f9099143832 ==============================
[0m17:32:55.777842 [info ] [MainThread]: Running with dbt=1.9.1
[0m17:32:55.778513 [debug] [MainThread]: running dbt with arguments {'printer_width': '80', 'indirect_selection': 'eager', 'log_cache_events': 'False', 'write_json': 'True', 'partial_parse': 'True', 'cache_selected_only': 'False', 'profiles_dir': '/app', 'debug': 'False', 'warn_error': 'None', 'log_path': 'logs', 'version_check': 'True', 'fail_fast': 'False', 'use_colors': 'True', 'use_experimental_parser': 'False', 'no_print': 'None', 'quiet': 'False', 'empty': 'None', 'warn_error_options': 'WarnErrorOptions(include=[], exclude=[])', 'introspect': 'True', 'invocation_command': 'dbt debug', 'log_format': 'default', 'target_path': 'None', 'static_parser': 'True', 'send_anonymous_usage_stats': 'True'}
[0m17:32:55.786587 [info ] [MainThread]: dbt version: 1.9.1
[0m17:32:55.787108 [info ] [MainThread]: python version: 3.13.1
[0m17:32:55.787653 [info ] [MainThread]: python path: /usr/local/bin/python3.13
[0m17:32:55.788112 [info ] [MainThread]: os info: Linux-5.15.153.1-microsoft-standard-WSL2-x86_64-with-glibc2.36
[0m17:32:55.848137 [info ] [MainThread]: Using profiles dir at /app
[0m17:32:55.849009 [info ] [MainThread]: Using profiles.yml file at /app/profiles.yml
[0m17:32:55.850986 [info ] [MainThread]: Using dbt_project.yml file at /app/dbt_project.yml
[0m17:32:55.852156 [info ] [MainThread]: Configuration:
[0m17:32:55.852711 [info ] [MainThread]:   profiles.yml file [[31mERROR invalid[0m]
[0m17:32:55.853342 [info ] [MainThread]:   dbt_project.yml file [[31mERROR not found[0m]
[0m17:32:55.853973 [info ] [MainThread]: Required dependencies:
[0m17:32:55.854692 [debug] [MainThread]: Executing "git --help"
[0m17:32:55.856231 [info ] [MainThread]:  - git [[31mERROR[0m]

[0m17:32:55.857151 [info ] [MainThread]: Connection test skipped since no profile was found
[0m17:32:55.857952 [info ] [MainThread]: [31m3 checks failed:[0m
[0m17:32:55.858711 [info ] [MainThread]: Could not load dbt_project.yml
Profile loading failed for the following reason:
Runtime Error
  Credentials in profile "magazorddw", target "prod" invalid: '5433' is not of type 'integer'


[0m17:32:55.859567 [info ] [MainThread]: Project loading failed for the following reason:
 project path </app/dbt_project.yml> not found

[0m17:32:55.860283 [info ] [MainThread]: Error from git --help: Could not find command, ensure it is in the user's PATH: "git"

[0m17:32:55.863301 [debug] [MainThread]: Resource report: {"command_name": "debug", "command_success": false, "command_wall_clock_time": 0.17928043, "process_in_blocks": "4152", "process_kernel_time": 0.246317, "process_mem_max_rss": "94808", "process_out_blocks": "1696", "process_user_time": 1.424356}
[0m17:32:55.864517 [debug] [MainThread]: Command `dbt debug` failed at 17:32:55.864277 after 0.18 seconds
[0m17:32:55.866009 [debug] [MainThread]: Sending event: {'category': 'dbt', 'action': 'invocation', 'label': 'end', 'context': [<snowplow_tracker.self_describing_json.SelfDescribingJson object at 0x7f5890585220>, <snowplow_tracker.self_describing_json.SelfDescribingJson object at 0x7f589059e330>, <snowplow_tracker.self_describing_json.SelfDescribingJson object at 0x7f5890eb1bf0>]}
[0m17:32:55.867722 [debug] [MainThread]: Flushing usage events
[0m17:32:56.831932 [debug] [MainThread]: An error was encountered while trying to flush usage events
[0m17:38:36.497123 [debug] [MainThread]: Sending event: {'category': 'dbt', 'action': 'invocation', 'label': 'start', 'context': [<snowplow_tracker.self_describing_json.SelfDescribingJson object at 0x7fea577b1160>, <snowplow_tracker.self_describing_json.SelfDescribingJson object at 0x7fea58be8e10>, <snowplow_tracker.self_describing_json.SelfDescribingJson object at 0x7fea56b0bed0>]}


============================== 17:38:36.505369 | b225f8fc-86af-4000-9e3f-afaa4238de12 ==============================
[0m17:38:36.505369 [info ] [MainThread]: Running with dbt=1.9.1
[0m17:38:36.506088 [debug] [MainThread]: running dbt with arguments {'printer_width': '80', 'indirect_selection': 'eager', 'write_json': 'True', 'log_cache_events': 'False', 'partial_parse': 'True', 'cache_selected_only': 'False', 'profiles_dir': '/app', 'debug': 'False', 'warn_error': 'None', 'log_path': 'logs', 'fail_fast': 'False', 'version_check': 'True', 'use_colors': 'True', 'use_experimental_parser': 'False', 'no_print': 'None', 'quiet': 'False', 'empty': 'None', 'warn_error_options': 'WarnErrorOptions(include=[], exclude=[])', 'static_parser': 'True', 'introspect': 'True', 'log_format': 'default', 'target_path': 'None', 'invocation_command': 'dbt debug', 'send_anonymous_usage_stats': 'True'}
[0m17:38:36.514859 [info ] [MainThread]: dbt version: 1.9.1
[0m17:38:36.515462 [info ] [MainThread]: python version: 3.13.1
[0m17:38:36.515917 [info ] [MainThread]: python path: /usr/local/bin/python3.13
[0m17:38:36.516328 [info ] [MainThread]: os info: Linux-5.15.153.1-microsoft-standard-WSL2-x86_64-with-glibc2.36
[0m17:38:36.589799 [info ] [MainThread]: Using profiles dir at /app
[0m17:38:36.590484 [info ] [MainThread]: Using profiles.yml file at /app/profiles.yml
[0m17:38:36.591055 [info ] [MainThread]: Using dbt_project.yml file at /app/dbt_project.yml
[0m17:38:36.591652 [info ] [MainThread]: Configuration:
[0m17:38:36.592076 [info ] [MainThread]:   profiles.yml file [[31mERROR invalid[0m]
[0m17:38:36.592460 [info ] [MainThread]:   dbt_project.yml file [[31mERROR not found[0m]
[0m17:38:36.592892 [info ] [MainThread]: Required dependencies:
[0m17:38:36.593344 [debug] [MainThread]: Executing "git --help"
[0m17:38:36.594437 [info ] [MainThread]:  - git [[31mERROR[0m]

[0m17:38:36.594929 [info ] [MainThread]: Connection test skipped since no profile was found
[0m17:38:36.595436 [info ] [MainThread]: [31m3 checks failed:[0m
[0m17:38:36.595884 [info ] [MainThread]: Could not load dbt_project.yml
Profile loading failed for the following reason:
Runtime Error
  Credentials in profile "magazorddw", target "prod" invalid: '5432' is not of type 'integer'


[0m17:38:36.596287 [info ] [MainThread]: Project loading failed for the following reason:
 project path </app/dbt_project.yml> not found

[0m17:38:36.596744 [info ] [MainThread]: Error from git --help: Could not find command, ensure it is in the user's PATH: "git"

[0m17:38:36.598995 [debug] [MainThread]: Resource report: {"command_name": "debug", "command_success": false, "command_wall_clock_time": 0.17601492, "process_in_blocks": "6352", "process_kernel_time": 0.236646, "process_mem_max_rss": "95032", "process_out_blocks": "1696", "process_user_time": 1.398362}
[0m17:38:36.599517 [debug] [MainThread]: Command `dbt debug` failed at 17:38:36.599406 after 0.18 seconds
[0m17:38:36.599958 [debug] [MainThread]: Sending event: {'category': 'dbt', 'action': 'invocation', 'label': 'end', 'context': [<snowplow_tracker.self_describing_json.SelfDescribingJson object at 0x7fea56089220>, <snowplow_tracker.self_describing_json.SelfDescribingJson object at 0x7fea560a2330>, <snowplow_tracker.self_describing_json.SelfDescribingJson object at 0x7fea56999bf0>]}
[0m17:38:36.600486 [debug] [MainThread]: Flushing usage events
[0m17:38:37.531540 [debug] [MainThread]: An error was encountered while trying to flush usage events
[0m14:51:18.611587 [debug] [MainThread]: Sending event: {'category': 'dbt', 'action': 'invocation', 'label': 'start', 'context': [<snowplow_tracker.self_describing_json.SelfDescribingJson object at 0x000002225FD59160>, <snowplow_tracker.self_describing_json.SelfDescribingJson object at 0x000002225DED0E10>, <snowplow_tracker.self_describing_json.SelfDescribingJson object at 0x000002226099E490>]}


============================== 14:51:18.617207 | efcf1b3a-805c-4561-a735-0d4203a3e08a ==============================
[0m14:51:18.617207 [info ] [MainThread]: Running with dbt=1.9.1
[0m14:51:18.617885 [debug] [MainThread]: running dbt with arguments {'printer_width': '80', 'indirect_selection': 'eager', 'log_cache_events': 'False', 'write_json': 'True', 'partial_parse': 'True', 'cache_selected_only': 'False', 'warn_error': 'None', 'fail_fast': 'False', 'version_check': 'True', 'log_path': 'logs', 'debug': 'False', 'profiles_dir': 'C:\\Users\\geron\\Desktop\\Projetos-Pessoais\\magazord-etl', 'use_colors': 'True', 'use_experimental_parser': 'False', 'empty': 'False', 'quiet': 'False', 'no_print': 'None', 'log_format': 'default', 'invocation_command': 'dbt run', 'static_parser': 'True', 'introspect': 'True', 'target_path': 'None', 'warn_error_options': 'WarnErrorOptions(include=[], exclude=[])', 'send_anonymous_usage_stats': 'True'}
[0m14:51:18.618363 [error] [MainThread]: Encountered an error:
Runtime Error
  No dbt_project.yml found at expected path C:\Users\geron\Desktop\Projetos-Pessoais\magazord-etl\dbt_project.yml
  Verify that each entry within packages.yml (and their transitive dependencies) contains a file named dbt_project.yml
  
[0m14:51:18.619256 [debug] [MainThread]: Command `dbt run` failed at 14:51:18.619111 after 0.12 seconds
[0m14:51:18.619611 [debug] [MainThread]: Sending event: {'category': 'dbt', 'action': 'invocation', 'label': 'end', 'context': [<snowplow_tracker.self_describing_json.SelfDescribingJson object at 0x0000022260E8CC30>, <snowplow_tracker.self_describing_json.SelfDescribingJson object at 0x0000022260D89EB0>, <snowplow_tracker.self_describing_json.SelfDescribingJson object at 0x0000022260D0E030>]}
[0m14:51:18.619971 [debug] [MainThread]: Flushing usage events
[0m14:51:19.667818 [debug] [MainThread]: An error was encountered while trying to flush usage events
[0m17:59:49.402969 [debug] [MainThread]: Sending event: {'category': 'dbt', 'action': 'invocation', 'label': 'start', 'context': [<snowplow_tracker.self_describing_json.SelfDescribingJson object at 0x7f6f64add160>, <snowplow_tracker.self_describing_json.SelfDescribingJson object at 0x7f6f65f04e10>, <snowplow_tracker.self_describing_json.SelfDescribingJson object at 0x7f6f63e3bed0>]}


============================== 17:59:49.412908 | 8f950434-5950-4702-b02c-9b4921db7a94 ==============================
[0m17:59:49.412908 [info ] [MainThread]: Running with dbt=1.9.1
[0m17:59:49.413664 [debug] [MainThread]: running dbt with arguments {'printer_width': '80', 'indirect_selection': 'eager', 'log_cache_events': 'False', 'write_json': 'True', 'partial_parse': 'True', 'cache_selected_only': 'False', 'profiles_dir': '/app', 'debug': 'False', 'version_check': 'True', 'log_path': 'logs', 'warn_error': 'None', 'fail_fast': 'False', 'use_colors': 'True', 'use_experimental_parser': 'False', 'empty': 'None', 'quiet': 'False', 'no_print': 'None', 'log_format': 'default', 'invocation_command': 'dbt debug', 'static_parser': 'True', 'introspect': 'True', 'target_path': 'None', 'warn_error_options': 'WarnErrorOptions(include=[], exclude=[])', 'send_anonymous_usage_stats': 'True'}
[0m17:59:49.432636 [info ] [MainThread]: dbt version: 1.9.1
[0m17:59:49.433257 [info ] [MainThread]: python version: 3.13.1
[0m17:59:49.433719 [info ] [MainThread]: python path: /usr/local/bin/python3.13
[0m17:59:49.434204 [info ] [MainThread]: os info: Linux-5.15.153.1-microsoft-standard-WSL2-x86_64-with-glibc2.36
[0m17:59:49.522271 [info ] [MainThread]: Using profiles dir at /app
[0m17:59:49.522935 [info ] [MainThread]: Using profiles.yml file at /app/profiles.yml
[0m17:59:49.523453 [info ] [MainThread]: Using dbt_project.yml file at /app/dbt_project.yml
[0m17:59:49.524213 [info ] [MainThread]: Configuration:
[0m17:59:49.524625 [info ] [MainThread]:   profiles.yml file [[31mERROR invalid[0m]
[0m17:59:49.525010 [info ] [MainThread]:   dbt_project.yml file [[31mERROR not found[0m]
[0m17:59:49.525423 [info ] [MainThread]: Required dependencies:
[0m17:59:49.525843 [debug] [MainThread]: Executing "git --help"
[0m17:59:49.526875 [info ] [MainThread]:  - git [[31mERROR[0m]

[0m17:59:49.527288 [info ] [MainThread]: Connection test skipped since no profile was found
[0m17:59:49.527733 [info ] [MainThread]: [31m3 checks failed:[0m
[0m17:59:49.528122 [info ] [MainThread]: Could not load dbt_project.yml
Profile loading failed for the following reason:
Runtime Error
  Credentials in profile "magazorddw", target "prod" invalid: '5432' is not of type 'integer'


[0m17:59:49.528544 [info ] [MainThread]: Project loading failed for the following reason:
 project path </app/dbt_project.yml> not found

[0m17:59:49.528935 [info ] [MainThread]: Error from git --help: Could not find command, ensure it is in the user's PATH: "git"

[0m17:59:49.530752 [debug] [MainThread]: Resource report: {"command_name": "debug", "command_success": false, "command_wall_clock_time": 0.18772294, "process_in_blocks": "54768", "process_kernel_time": 0.327132, "process_mem_max_rss": "94904", "process_out_blocks": "1696", "process_user_time": 1.533432}
[0m17:59:49.531272 [debug] [MainThread]: Command `dbt debug` failed at 17:59:49.531168 after 0.19 seconds
[0m17:59:49.531698 [debug] [MainThread]: Sending event: {'category': 'dbt', 'action': 'invocation', 'label': 'end', 'context': [<snowplow_tracker.self_describing_json.SelfDescribingJson object at 0x7f6f633b9220>, <snowplow_tracker.self_describing_json.SelfDescribingJson object at 0x7f6f633d2330>, <snowplow_tracker.self_describing_json.SelfDescribingJson object at 0x7f6f63cc5bf0>]}
[0m17:59:49.532152 [debug] [MainThread]: Flushing usage events
[0m17:59:50.519296 [debug] [MainThread]: An error was encountered while trying to flush usage events
[0m18:10:56.448091 [debug] [MainThread]: Sending event: {'category': 'dbt', 'action': 'invocation', 'label': 'start', 'context': [<snowplow_tracker.self_describing_json.SelfDescribingJson object at 0x7fb4c68c8590>, <snowplow_tracker.self_describing_json.SelfDescribingJson object at 0x7fb4c7c54a50>, <snowplow_tracker.self_describing_json.SelfDescribingJson object at 0x7fb4c6076490>]}


============================== 18:10:56.451629 | 3d3934bc-aabc-457f-9ad8-aa52ff382235 ==============================
[0m18:10:56.451629 [info ] [MainThread]: Running with dbt=1.9.1
[0m18:10:56.452375 [debug] [MainThread]: running dbt with arguments {'printer_width': '80', 'indirect_selection': 'eager', 'log_cache_events': 'False', 'write_json': 'True', 'partial_parse': 'True', 'cache_selected_only': 'False', 'profiles_dir': '/app', 'debug': 'False', 'fail_fast': 'False', 'log_path': 'logs', 'warn_error': 'None', 'version_check': 'True', 'use_colors': 'True', 'use_experimental_parser': 'False', 'empty': 'None', 'quiet': 'False', 'no_print': 'None', 'warn_error_options': 'WarnErrorOptions(include=[], exclude=[])', 'static_parser': 'True', 'invocation_command': 'dbt debug', 'introspect': 'True', 'target_path': 'None', 'log_format': 'default', 'send_anonymous_usage_stats': 'True'}
[0m18:10:56.460315 [info ] [MainThread]: dbt version: 1.9.1
[0m18:10:56.460951 [info ] [MainThread]: python version: 3.13.1
[0m18:10:56.461384 [info ] [MainThread]: python path: /usr/local/bin/python3.13
[0m18:10:56.461770 [info ] [MainThread]: os info: Linux-5.15.153.1-microsoft-standard-WSL2-x86_64-with-glibc2.36
[0m18:10:56.524545 [info ] [MainThread]: Using profiles dir at /app
[0m18:10:56.525223 [info ] [MainThread]: Using profiles.yml file at /app/profiles.yml
[0m18:10:56.525731 [info ] [MainThread]: Using dbt_project.yml file at /app/dbt_project.yml
[0m18:10:56.526320 [info ] [MainThread]: Configuration:
[0m18:10:56.526737 [info ] [MainThread]:   profiles.yml file [[31mERROR invalid[0m]
[0m18:10:56.527190 [info ] [MainThread]:   dbt_project.yml file [[31mERROR not found[0m]
[0m18:10:56.527668 [info ] [MainThread]: Required dependencies:
[0m18:10:56.528153 [debug] [MainThread]: Executing "git --help"
[0m18:10:56.529251 [info ] [MainThread]:  - git [[31mERROR[0m]

[0m18:10:56.529685 [info ] [MainThread]: Connection test skipped since no profile was found
[0m18:10:56.530159 [info ] [MainThread]: [31m3 checks failed:[0m
[0m18:10:56.530598 [info ] [MainThread]: Could not load dbt_project.yml
Profile loading failed for the following reason:
Runtime Error
  Credentials in profile "magazorddw", target "prod" invalid: '5432' is not of type 'integer'


[0m18:10:56.531069 [info ] [MainThread]: Project loading failed for the following reason:
 project path </app/dbt_project.yml> not found

[0m18:10:56.531460 [info ] [MainThread]: Error from git --help: Could not find command, ensure it is in the user's PATH: "git"

[0m18:10:56.532448 [debug] [MainThread]: Resource report: {"command_name": "debug", "command_success": false, "command_wall_clock_time": 0.14964506, "process_in_blocks": "16184", "process_kernel_time": 0.235814, "process_mem_max_rss": "94164", "process_out_blocks": "0", "process_user_time": 1.564953}
[0m18:10:56.532995 [debug] [MainThread]: Command `dbt debug` failed at 18:10:56.532859 after 0.15 seconds
[0m18:10:56.533507 [debug] [MainThread]: Sending event: {'category': 'dbt', 'action': 'invocation', 'label': 'end', 'context': [<snowplow_tracker.self_describing_json.SelfDescribingJson object at 0x7fb4c5aecfc0>, <snowplow_tracker.self_describing_json.SelfDescribingJson object at 0x7fb4c50fd7f0>, <snowplow_tracker.self_describing_json.SelfDescribingJson object at 0x7fb4c5bcd8c0>]}
[0m18:10:56.533993 [debug] [MainThread]: Flushing usage events
[0m18:10:57.563305 [debug] [MainThread]: An error was encountered while trying to flush usage events
[0m18:12:29.225921 [debug] [MainThread]: Sending event: {'category': 'dbt', 'action': 'invocation', 'label': 'start', 'context': [<snowplow_tracker.self_describing_json.SelfDescribingJson object at 0x7f031aafc590>, <snowplow_tracker.self_describing_json.SelfDescribingJson object at 0x7f031be88a50>, <snowplow_tracker.self_describing_json.SelfDescribingJson object at 0x7f031a29e490>]}


============================== 18:12:29.229206 | e3038fe6-022e-4500-90f2-84ce01ef9b1d ==============================
[0m18:12:29.229206 [info ] [MainThread]: Running with dbt=1.9.1
[0m18:12:29.229846 [debug] [MainThread]: running dbt with arguments {'printer_width': '80', 'indirect_selection': 'eager', 'log_cache_events': 'False', 'write_json': 'True', 'partial_parse': 'True', 'cache_selected_only': 'False', 'warn_error': 'None', 'fail_fast': 'False', 'debug': 'False', 'log_path': 'logs', 'profiles_dir': '/app', 'version_check': 'True', 'use_colors': 'True', 'use_experimental_parser': 'False', 'no_print': 'None', 'quiet': 'False', 'empty': 'None', 'log_format': 'default', 'static_parser': 'True', 'introspect': 'True', 'invocation_command': 'dbt debug', 'target_path': 'None', 'warn_error_options': 'WarnErrorOptions(include=[], exclude=[])', 'send_anonymous_usage_stats': 'True'}
[0m18:12:29.288185 [info ] [MainThread]: dbt version: 1.9.1
[0m18:12:29.288849 [info ] [MainThread]: python version: 3.13.1
[0m18:12:29.289357 [info ] [MainThread]: python path: /usr/local/bin/python3.13
[0m18:12:29.289802 [info ] [MainThread]: os info: Linux-5.15.153.1-microsoft-standard-WSL2-x86_64-with-glibc2.36
[0m18:12:29.341988 [info ] [MainThread]: Using profiles dir at /app
[0m18:12:29.342638 [info ] [MainThread]: Using profiles.yml file at /app/profiles.yml
[0m18:12:29.343223 [info ] [MainThread]: Using dbt_project.yml file at /app/dbt_project.yml
[0m18:12:29.343827 [info ] [MainThread]: Configuration:
[0m18:12:29.344242 [info ] [MainThread]:   profiles.yml file [[31mERROR invalid[0m]
[0m18:12:29.344629 [info ] [MainThread]:   dbt_project.yml file [[31mERROR not found[0m]
[0m18:12:29.345034 [info ] [MainThread]: Required dependencies:
[0m18:12:29.345438 [debug] [MainThread]: Executing "git --help"
[0m18:12:29.346586 [info ] [MainThread]:  - git [[31mERROR[0m]

[0m18:12:29.347006 [info ] [MainThread]: Connection test skipped since no profile was found
[0m18:12:29.347470 [info ] [MainThread]: [31m3 checks failed:[0m
[0m18:12:29.347875 [info ] [MainThread]: Could not load dbt_project.yml
Profile loading failed for the following reason:
Runtime Error
  Credentials in profile "magazorddw", target "prod" invalid: '5432' is not of type 'integer'


[0m18:12:29.348270 [info ] [MainThread]: Project loading failed for the following reason:
 project path </app/dbt_project.yml> not found

[0m18:12:29.348667 [info ] [MainThread]: Error from git --help: Could not find command, ensure it is in the user's PATH: "git"

[0m18:12:29.349672 [debug] [MainThread]: Resource report: {"command_name": "debug", "command_success": false, "command_wall_clock_time": 0.18073086, "process_in_blocks": "8", "process_kernel_time": 0.191751, "process_mem_max_rss": "94036", "process_out_blocks": "0", "process_user_time": 1.30842}
[0m18:12:29.350181 [debug] [MainThread]: Command `dbt debug` failed at 18:12:29.350075 after 0.18 seconds
[0m18:12:29.350670 [debug] [MainThread]: Sending event: {'category': 'dbt', 'action': 'invocation', 'label': 'end', 'context': [<snowplow_tracker.self_describing_json.SelfDescribingJson object at 0x7f0319d18fc0>, <snowplow_tracker.self_describing_json.SelfDescribingJson object at 0x7f0319d257f0>, <snowplow_tracker.self_describing_json.SelfDescribingJson object at 0x7f0319df98c0>]}
[0m18:12:29.351268 [debug] [MainThread]: Flushing usage events
[0m18:12:30.246181 [debug] [MainThread]: An error was encountered while trying to flush usage events
[0m18:14:25.395310 [debug] [MainThread]: Sending event: {'category': 'dbt', 'action': 'invocation', 'label': 'start', 'context': [<snowplow_tracker.self_describing_json.SelfDescribingJson object at 0x7f08e5b24d70>, <snowplow_tracker.self_describing_json.SelfDescribingJson object at 0x7f08e6f38910>, <snowplow_tracker.self_describing_json.SelfDescribingJson object at 0x7f08e534e850>]}


============================== 18:14:25.399169 | f80d316e-510d-43c4-b6d7-afd1babd7ba1 ==============================
[0m18:14:25.399169 [info ] [MainThread]: Running with dbt=1.9.1
[0m18:14:25.399867 [debug] [MainThread]: running dbt with arguments {'printer_width': '80', 'indirect_selection': 'eager', 'write_json': 'True', 'log_cache_events': 'False', 'partial_parse': 'True', 'cache_selected_only': 'False', 'warn_error': 'None', 'version_check': 'True', 'fail_fast': 'False', 'log_path': 'logs', 'profiles_dir': '/app', 'debug': 'False', 'use_colors': 'True', 'use_experimental_parser': 'False', 'empty': 'False', 'quiet': 'False', 'no_print': 'None', 'log_format': 'default', 'static_parser': 'True', 'introspect': 'True', 'invocation_command': 'dbt run', 'target_path': 'None', 'warn_error_options': 'WarnErrorOptions(include=[], exclude=[])', 'send_anonymous_usage_stats': 'True'}
[0m18:14:25.400562 [error] [MainThread]: Encountered an error:
Runtime Error
  No dbt_project.yml found at expected path /app/dbt_project.yml
  Verify that each entry within packages.yml (and their transitive dependencies) contains a file named dbt_project.yml
  
[0m18:14:25.401861 [debug] [MainThread]: Resource report: {"command_name": "run", "command_success": false, "command_wall_clock_time": 0.06304206, "process_in_blocks": "8080", "process_kernel_time": 0.117554, "process_mem_max_rss": "89744", "process_out_blocks": "1352", "process_user_time": 1.271722}
[0m18:14:25.402342 [debug] [MainThread]: Command `dbt run` failed at 18:14:25.402241 after 0.06 seconds
[0m18:14:25.402812 [debug] [MainThread]: Sending event: {'category': 'dbt', 'action': 'invocation', 'label': 'end', 'context': [<snowplow_tracker.self_describing_json.SelfDescribingJson object at 0x7f08e4f4fe10>, <snowplow_tracker.self_describing_json.SelfDescribingJson object at 0x7f08e4ec8050>, <snowplow_tracker.self_describing_json.SelfDescribingJson object at 0x7f08e4eee8b0>]}
[0m18:14:25.403285 [debug] [MainThread]: Flushing usage events
[0m18:14:26.411392 [debug] [MainThread]: An error was encountered while trying to flush usage events
[0m18:57:05.825613 [debug] [MainThread]: Sending event: {'category': 'dbt', 'action': 'invocation', 'label': 'start', 'context': [<snowplow_tracker.self_describing_json.SelfDescribingJson object at 0x7f95daa79160>, <snowplow_tracker.self_describing_json.SelfDescribingJson object at 0x7f95dbe80e10>, <snowplow_tracker.self_describing_json.SelfDescribingJson object at 0x7f95d9ddbed0>]}


============================== 18:57:05.835576 | 698cecbd-e3d5-43d6-b410-d78cc019a97f ==============================
[0m18:57:05.835576 [info ] [MainThread]: Running with dbt=1.9.1
[0m18:57:05.836244 [debug] [MainThread]: running dbt with arguments {'printer_width': '80', 'indirect_selection': 'eager', 'log_cache_events': 'False', 'write_json': 'True', 'partial_parse': 'True', 'cache_selected_only': 'False', 'warn_error': 'None', 'fail_fast': 'False', 'version_check': 'True', 'log_path': 'logs', 'profiles_dir': '/app', 'debug': 'False', 'use_colors': 'True', 'use_experimental_parser': 'False', 'empty': 'None', 'quiet': 'False', 'no_print': 'None', 'log_format': 'default', 'static_parser': 'True', 'warn_error_options': 'WarnErrorOptions(include=[], exclude=[])', 'invocation_command': 'dbt debug', 'target_path': 'None', 'introspect': 'True', 'send_anonymous_usage_stats': 'True'}
[0m18:57:05.857176 [info ] [MainThread]: dbt version: 1.9.1
[0m18:57:05.857825 [info ] [MainThread]: python version: 3.13.1
[0m18:57:05.858230 [info ] [MainThread]: python path: /usr/local/bin/python3.13
[0m18:57:05.858619 [info ] [MainThread]: os info: Linux-5.15.153.1-microsoft-standard-WSL2-x86_64-with-glibc2.36
[0m18:57:05.950197 [info ] [MainThread]: Using profiles dir at /app
[0m18:57:05.950788 [info ] [MainThread]: Using profiles.yml file at /app/profiles.yml
[0m18:57:05.951202 [info ] [MainThread]: Using dbt_project.yml file at /app/dbt_project.yml
[0m18:57:05.951760 [info ] [MainThread]: Configuration:
[0m18:57:05.952142 [info ] [MainThread]:   profiles.yml file [[31mERROR invalid[0m]
[0m18:57:05.952519 [info ] [MainThread]:   dbt_project.yml file [[31mERROR not found[0m]
[0m18:57:05.952895 [info ] [MainThread]: Required dependencies:
[0m18:57:05.953314 [debug] [MainThread]: Executing "git --help"
[0m18:57:05.955567 [info ] [MainThread]:  - git [[31mERROR[0m]

[0m18:57:05.955991 [info ] [MainThread]: Connection test skipped since no profile was found
[0m18:57:05.956425 [info ] [MainThread]: [31m3 checks failed:[0m
[0m18:57:05.956817 [info ] [MainThread]: Could not load dbt_project.yml
Profile loading failed for the following reason:
Runtime Error
  Credentials in profile "magazorddw", target "prod" invalid: '5433' is not of type 'integer'


[0m18:57:05.957191 [info ] [MainThread]: Project loading failed for the following reason:
 project path </app/dbt_project.yml> not found

[0m18:57:05.957588 [info ] [MainThread]: Error from git --help: Could not find command, ensure it is in the user's PATH: "git"

[0m18:57:05.959322 [debug] [MainThread]: Resource report: {"command_name": "debug", "command_success": false, "command_wall_clock_time": 0.19428912, "process_in_blocks": "79992", "process_kernel_time": 0.231548, "process_mem_max_rss": "94696", "process_out_blocks": "1696", "process_user_time": 1.521604}
[0m18:57:05.959807 [debug] [MainThread]: Command `dbt debug` failed at 18:57:05.959701 after 0.19 seconds
[0m18:57:05.960224 [debug] [MainThread]: Sending event: {'category': 'dbt', 'action': 'invocation', 'label': 'end', 'context': [<snowplow_tracker.self_describing_json.SelfDescribingJson object at 0x7f95d9339220>, <snowplow_tracker.self_describing_json.SelfDescribingJson object at 0x7f95d9352330>, <snowplow_tracker.self_describing_json.SelfDescribingJson object at 0x7f95d9c5dbf0>]}
[0m18:57:05.960731 [debug] [MainThread]: Flushing usage events
[0m18:57:07.322970 [debug] [MainThread]: An error was encountered while trying to flush usage events
[0m18:26:34.049333 [debug] [MainThread]: Sending event: {'category': 'dbt', 'action': 'invocation', 'label': 'start', 'context': [<snowplow_tracker.self_describing_json.SelfDescribingJson object at 0x000001ED792A6510>, <snowplow_tracker.self_describing_json.SelfDescribingJson object at 0x000001ED7A241E50>, <snowplow_tracker.self_describing_json.SelfDescribingJson object at 0x000001ED7A241950>]}


============================== 18:26:34.057092 | 1652d06e-15ca-472e-a19c-112f66bf52a7 ==============================
[0m18:26:34.057092 [info ] [MainThread]: Running with dbt=1.9.1
[0m18:26:34.057902 [debug] [MainThread]: running dbt with arguments {'printer_width': '80', 'indirect_selection': 'eager', 'write_json': 'True', 'log_cache_events': 'False', 'partial_parse': 'True', 'cache_selected_only': 'False', 'warn_error': 'None', 'debug': 'False', 'profiles_dir': 'C:\\Users\\geron\\Desktop\\Projetos-Pessoais\\magazord-etl', 'log_path': 'logs', 'fail_fast': 'False', 'version_check': 'True', 'use_colors': 'True', 'use_experimental_parser': 'False', 'no_print': 'None', 'quiet': 'False', 'empty': 'False', 'warn_error_options': 'WarnErrorOptions(include=[], exclude=[])', 'introspect': 'True', 'invocation_command': 'dbt ', 'static_parser': 'True', 'target_path': 'None', 'log_format': 'default', 'send_anonymous_usage_stats': 'True'}
[0m18:26:34.058373 [error] [MainThread]: Encountered an error:
Runtime Error
  No dbt_project.yml found at expected path C:\Users\geron\Desktop\Projetos-Pessoais\magazord-etl\dbt_project.yml
  Verify that each entry within packages.yml (and their transitive dependencies) contains a file named dbt_project.yml
  
[0m18:26:34.059589 [debug] [MainThread]: Command `cli run` failed at 18:26:34.059450 after 0.06 seconds
[0m18:26:34.059923 [debug] [MainThread]: Sending event: {'category': 'dbt', 'action': 'invocation', 'label': 'end', 'context': [<snowplow_tracker.self_describing_json.SelfDescribingJson object at 0x000001ED7B8455B0>, <snowplow_tracker.self_describing_json.SelfDescribingJson object at 0x000001ED7A815D90>, <snowplow_tracker.self_describing_json.SelfDescribingJson object at 0x000001ED7A71D260>]}
[0m18:26:34.060246 [debug] [MainThread]: Flushing usage events
[0m18:26:34.902005 [debug] [MainThread]: An error was encountered while trying to flush usage events
